Workbook
Name Slicer_Month: #N/A
Name Slicer_Year: #N/A

Sheet Sheet1
A2: Battery | D2: Panel | G2: Data Center
A3: Row Labels | B3: Average of Temp | D3: Row Labels | E3: Average of Temp2 | G3: Row Labels | H3: Average of Temp3
A4: 45809 | B4: 18.575382 | D4: 45809 | E4: 20.208645 | G4: 45809 | H4: 30.929687
A5: Jun | B5: 18.575382 | D5: Jun | E5: 20.208645 | G5: Jun | H5: 30.929687
A6: 45810 | B6: 18.526458 | D6: 45810 | E6: 20.159513 | G6: 45810 | H6: 30.644895
A7: Jun | B7: 18.526458 | D7: Jun | E7: 20.159513 | G7: Jun | H7: 30.644895
A8: 45811 | B8: 18.479409 | D8: 45811 | E8: 20.024861 | G8: 45811 | H8: 30.82552
A9: Jun | B9: 18.479409 | D9: Jun | E9: 20.024861 | G9: Jun | H9: 30.82552
A10: 45812 | B10: 18.456736 | D10: 45812 | E10: 21.4 | G10: 45812 | H10: 31.044097
A11: Jun | B11: 18.456736 | D11: Jun | E11: 21.4 | G11: Jun | H11: 31.044097
A12: 45813 | B12: 18.477083 | D12: 45813 | E12: 22.482569 | G12: 45813 | H12: 31.32427
A13: Jun | B13: 18.477083 | D13: Jun | E13: 22.482569 | G13: Jun | H13: 31.32427
A14: 45814 | B14: 18.518923 | D14: 45814 | E14: 22.572708 | G14: 45814 | H14: 31.330833
A15: Jun | B15: 18.518923 | D15: Jun | E15: 22.572708 | G15: Jun | H15: 31.330833
A16: 45815 | B16: 21.095104 | D16: 45815 | E16: 22.573819 | G16: 45815 | H16: 30.557881
A17: Jun | B17: 21.095104 | D17: Jun | E17: 22.573819 | G17: Jun | H17: 30.557881
A18: 45816 | B18: 21.488159 | D18: 45816 | E18: 21.095104 | G18: 45816 | H18: 29.139548
A19: Jun | B19: 21.488159 | D19: Jun | E19: 21.095104 | G19: Jun | H19: 29.139548
A20: 45817 | B20: 20.31184 | D20: 45817 | E20: 19.372673 | G20: 45817 | H20: 28.148333
A21: Jun | B21: 20.31184 | D21: Jun | E21: 19.372673 | G21: Jun | H21: 28.148333
A22: 45818 | B22: 19.23368 | D22: 45818 | E22: 19.370937 | G22: 45818 | H22: 27.569895
A23: Jun | B23: 19.23368 | D23: Jun | E23: 19.370937 | G23: Jun | H23: 27.569895
A24: 45819 | B24: 19.263993 | D24: 45819 | E24: 19.50684 | G24: 45819 | H24: 28.576735
A25: Jun | B25: 19.263993 | D25: Jun | E25: 19.50684 | G25: Jun | H25: 28.576735
A26: 45820 | B26: 19.762534 | D26: 45820 | E26: 21.494097 | G26: 45820 | H26: 29.481458
A27: Jun | B27: 19.762534 | D27: Jun | E27: 21.494097 | G27: Jun | H27: 29.481458
A28: 45821 | B28: 19.455486 | D28: 45821 | E28: 22.04493 | G28: 45821 | H28: 29.910902
A29: Jun | B29: 19.455486 | D29: Jun | E29: 22.04493 | G29: Jun | H29: 29.910902
A30: 45822 | B30: 19.305555 | D30: 45822 | E30: 22.022083 | G30: 45822 | H30: 29.717985
A31: Jun | B31: 19.305555 | D31: Jun | E31: 22.022083 | G31: Jun | H31: 29.717985
A32: 45823 | B32: 19.343611 | D32: 45823 | E32: 22.545486 | G32: 45823 | H32: 29.539166
A33: Jun | B33: 19.343611 | D33: Jun | E33: 22.545486 | G33: Jun | H33: 29.539166
A34: 45824 | B34: 21.114062 | D34: 45824 | E34: 22.614062 | G34: 45824 | H34: 29.964687
A35: Jun | B35: 21.114062 | D35: Jun | E35: 22.614062 | G35: Jun | H35: 29.964687
A36: 45825 | B36: 22.054166 | D36: 45825 | E36: 22.697847 | G36: 45825 | H36: 30.394479
A37: Jun | B37: 22.054166 | D37: Jun | E37: 22.697847 | G37: Jun | H37: 30.394479
A38: 45826 | B38: 21.00475 | D38: 45826 | E38: 20.846461 | G38: 45826 | H38: 30.23929
A39: Jun | B39: 21.00475 | D39: Jun | E39: 20.846461 | G39: Jun | H39: 30.23929
A40: 45827 | B40: 19.487604 | D40: 45827 | E40: 17.389062 | G40: 45827 | H40: 29.546041
A41: Jun | B41: 19.487604 | D41: Jun | E41: 17.389062 | G41: Jun | H41: 29.546041
...

Sheet Sheet3

Sheet Database
E1: ROOM | U1: CRAC
E2: Battery | G2: Panel | I2: Data Center | K2: Google 1 | M2: Google 2 | O2: Meta | Q2: CCG | S2: TPN | U2: 2.1.A - CCG | W2: 2.1.B - CCG | Y2: 2.2.A - Data Center | AA2: 2.2.B - Data Center | AC2: 2.2.C - Data Center | AE2: 3.1.A - TPN | AG2: 3.1.B - TPN
A3: Date | B3: Year | C3: Month | D3: Week | E3: Temp | F3: Humi | G3: Temp | H3: Humi | I3: Temp | J3: Humi | K3: Temp | L3: Humi | M3: Temp | N3: Humi | O3: Temp | P3: Humi | Q3: Temp | R3: Humi | S3: Temp | T3: Humi | U3: Temp | V3: Humi | W3: Temp | X3: Humi | Y3: Temp | Z3: Humi | AA3: Temp | AB3: Humi | AC3: Temp | AD3: Humi | AE3: Temp | AF3: Humi | AG3: Temp | AH3: Humi
A4: 46023 | B4: 2026 | C4: January | D4: ="Week-" & INT((DAY(A4)-1)/7)+1 -> Week-1 | E4: 18.57184 | F4: 52.48594 | G4: 20.90285 | H4: 71.48121 | I4: 28.56087 | J4: 65.42024 | K4: 28.37542 | L4: 69.35969 | M4: 28.3575 | N4: 69.30167 | O4: 28.67684 | P4: 66.81948 | Q4: 18.62288 | R4: 63.66437 | S4: 30.75632 | T4: 71.81778 | U4: 17.47917 | V4: 61.62118 | W4: 17.48021 | X4: 61.56007 | Y4: 31.54201 | Z4: 52.91979 | AA4: 31.82535 | AB4: 50.47222 | AC4: 30.35104 | AD4: 54.42708 | AE4: 33.99583 | AF4: 57.15278 | AG4: 34.43264 | AH4: 53.46806
A5: 46024 | B5: 2026 | C5: January | D5: ="Week-" & INT((DAY(A5)-1)/7)+1 -> Week-1 | E5: 18.59521 | F5: 52.94371 | G5: 20.26194 | H5: 65.59937 | I5: 28.65194 | J5: 62.97642 | K5: 28.63073 | L5: 64.28795 | M5: 28.63104 | N5: 64.07778 | O5: 28.88222 | P5: 63.28045 | Q5: 19.09285 | R5: 63.62035 | S5: 30.99507 | T5: 71.20038 | U5: 17.45486 | V5: 64.18611 | W5: 17.45486 | X5: 64.18056 | Y5: 31.64965 | Z5: 50.37222 | AA5: 32.00104 | AB5: 47.3191 | AC5: 30.56979 | AD5: 50.26562 | AE5: 34.27674 | AF5: 56.60556 | AG5: 34.7066 | AH5: 52.95208
A6: 46025 | B6: 2026 | C6: January | D6: ="Week-" & INT((DAY(A6)-1)/7)+1 -> Week-1 | E6: 20.94139 | F6: 48.43559 | G6: 19.53556 | H6: 67.87781 | I6: 28.28344 | J6: 64.43021 | K6: 27.95448 | L6: 68.44604 | M6: 27.9243 | N6: 68.24809 | O6: 28.25653 | P6: 66.65816 | Q6: 18.61035 | R6: 64.27267 | S6: 30.43774 | T6: 71.04465 | U6: 17.50174 | V6: 62.13646 | W6: 17.49757 | X6: 62.07882 | Y6: 31.22639 | Z6: 52.31285 | AA6: 31.4875 | AB6: 50.16979 | AC6: 29.98403 | AD6: 53.79063 | AE6: 33.63889 | AF6: 56.75486 | AG6: 34.08611 | AH6: 53.01979
A7: 46026 | B7: 2026 | C7: January | D7: ="Week-" & INT((DAY(A7)-1)/7)+1 -> Week-1 | E7: 19.68635 | F7: 49.85337 | G7: 20.07719 | H7: 63.15996 | I7: 27.78632 | J7: 63.14371 | K7: 27.45955 | L7: 67.40337 | M7: 27.40986 | N7: 67.44802 | O7: 27.77264 | P7: 65.21246 | Q7: 18.95521 | R7: 65.14503 | S7: 29.99778 | T7: 72.49055 | U7: 17.48299 | V7: 65.07847 | W7: 17.48889 | X7: 65.09792 | Y7: 30.70451 | Z7: 50.93333 | AA7: 30.95868 | AB7: 48.83785 | AC7: 29.43299 | AD7: 52.69132 | AE7: 33.27847 | AF7: 57.8375 | AG7: 33.74826 | AH7: 54.13333
A8: 46027 | B8: 2026 | C8: January | D8: ="Week-" & INT((DAY(A8)-1)/7)+1 -> Week-1 | E8: 19.66069 | F8: 54.66205 | G8: 18.07368 | H8: 55.83358 | I8: 27.86701 | J8: 65.30423 | K8: 27.93792 | L8: 66.96055 | M8: 27.92406 | N8: 67.10726 | O8: 28.18514 | P8: 65.44253 | Q8: 18.54146 | R8: 63.93802 | S8: 30.3699 | T8: 73.73732 | U8: 17.45903 | V8: 61.88438 | W8: 17.45972 | X8: 61.86979 | Y8: 30.91389 | Z8: 51.36285 | AA8: 31.27708 | AB8: 48.88264 | AC8: 29.80833 | AD8: 52.56354 | AE8: 33.72292 | AF8: 58.57778 | AG8: 34.15208 | AH8: 54.77639
A9: 46028 | B9: 2026 | C9: January | D9: ="Week-" & INT((DAY(A9)-1)/7)+1 -> Week-1 | E9: 18.79632 | F9: 52.76111 | G9: 18.65448 | H9: 62.74837 | I9: 28.28236 | J9: 65.04663 | K9: 28.44965 | L9: 65.55837 | M9: 28.45351 | N9: 65.69514 | O9: 28.67149 | P9: 64.50108 | Q9: 18.92826 | R9: 63.64167 | S9: 31.45153 | T9: 71.2809 | U9: 17.44792 | V9: 64.23958 | W9: 17.44826 | X9: 64.28194 | Y9: 31.42847 | Z9: 50.47465 | AA9: 31.75139 | AB9: 47.79167 | AC9: 30.34201 | AD9: 51.34306 | AE9: 34.90417 | AF9: 56.08194 | AG9: 35.29167 | AH9: 52.55417
A10: 46029 | B10: 2026 | C10: January | D10: ="Week-" & INT((DAY(A10)-1)/7)+1 -> Week-1 | E10: 18.24031 | F10: 53.27187 | G10: 20.10271 | H10: 64.10149 | I10: 28.53104 | J10: 65.57514 | K10: 28.5426 | L10: 67.77361 | M10: 28.52382 | N10: 68.03045 | O10: 28.8075 | P10: 65.22118 | Q10: 18.60726 | R10: 63.79271 | S10: 31.48708 | T10: 71.93871 | U10: 17.47049 | V10: 61.99965 | W10: 17.47118 | X10: 62.04514 | Y10: 31.66285 | Z10: 50.6934 | AA10: 32.00937 | AB10: 48.38681 | AC10: 30.56632 | AD10: 52.44167 | AE10: 34.85 | AF10: 57.00174 | AG10: 35.27813 | AH10: 53.26215
A11: 46030 | B11: 2026 | C11: January | D11: ="Week-" & INT((DAY(A11)-1)/7)+1 -> Week-2 | E11: 19.68163 | F11: 52.69246 | G11: 19.3883 | H11: 66.04135 | I11: 28.44517 | J11: 66.59545 | K11: 28.45604 | L11: 68.66135 | M11: 28.46288 | N11: 68.55642 | O11: 28.72285 | P11: 66.32726 | Q11: 18.88542 | R11: 63.52944 | S11: 31.20934 | T11: 70.9683 | U11: 17.42743 | V11: 64.06875 | W11: 17.42222 | X11: 64.06562 | Y11: 31.49861 | Z11: 53.58958 | AA11: 31.7441 | AB11: 50.97743 | AC11: 30.32014 | AD11: 54.56215 | AE11: 34.55764 | AF11: 56.23507 | AG11: 34.96771 | AH11: 52.52222
A12: 46031 | B12: 2026 | C12: January | D12: ="Week-" & INT((DAY(A12)-1)/7)+1 -> Week-2 | E12: 18.77955 | F12: 54.12455 | G12: 18.30177 | H12: 65.62014 | I12: 28.2525 | J12: 67.7767 | K12: 28.15024 | L12: 71.49028 | M12: 28.14917 | N12: 71.47594 | O12: 28.45194 | P12: 68.24038 | Q12: 18.63604 | R12: 64.7192 | S12: 30.83451 | T12: 71.01392 | U12: 17.52813 | V12: 63.59757 | W12: 17.53125 | X12: 63.62049 | Y12: 31.28715 | Z12: 54.91944 | AA12: 31.56319 | AB12: 52.89479 | AC12: 30.03194 | AD12: 57.15625 | AE12: 34.04132 | AF12: 56.48715 | AG12: 34.47396 | AH12: 52.97569
A13: 46032 | B13: 2026 | C13: January | D13: ="Week-" & INT((DAY(A13)-1)/7)+1 -> Week-2 | E13: 18.18076 | F13: 56.57722 | G13: 17.33271 | H13: 61.24434 | I13: 27.91354 | J13: 69.25653 | K13: 27.71691 | L13: 72.99417 | M13: 27.71229 | N13: 72.93392 | O13: 28.07517 | P13: 69.60601 | Q13: 18.93205 | R13: 64.14548 | S13: 30.37448 | T13: 71.93059 | U13: 17.4559 | V13: 64.66389 | W13: 17.45625 | X13: 64.6816 | Y13: 30.95208 | Z13: 55.46736 | AA13: 31.18472 | AB13: 53.82639 | AC13: 29.62986 | AD13: 58.95451 | AE13: 33.58507 | AF13: 57.42569 | AG13: 34.00174 | AH13: 53.88785
A14: 46033 | B14: 2026 | C14: January | D14: ="Week-" & INT((DAY(A14)-1)/7)+1 -> Week-2 | E14: 18.21986 | F14: 57.73771 | G14: 18.83726 | H14: 67.00503 | I14: 27.60552 | J14: 70.10333 | K14: 27.23406 | L14: 73.04285 | M14: 27.21903 | N14: 72.9609 | O14: 27.6151 | P14: 70.45118 | Q14: 18.58253 | R14: 65.33024 | S14: 29.99889 | T14: 72.6634 | U14: 17.52882 | V14: 63.72604 | W14: 17.52847 | X14: 63.74201 | Y14: 30.5875 | Z14: 55.69792 | AA14: 30.82778 | AB14: 54.01215 | AC14: 29.2809 | AD14: 58.6691 | AE14: 33.19271 | AF14: 58.16181 | AG14: 33.69306 | AH14: 54.25382
A15: 46034 | B15: 2026 | C15: January | D15: ="Week-" & INT((DAY(A15)-1)/7)+1 -> Week-2 | E15: 18.23656 | F15: 57.6759 | G15: 19.81472 | H15: 62.96278 | I15: 26.81417 | J15: 69.62274 | K15: 26.1433 | L15: 72.94816 | M15: 26.05642 | N15: 72.9908 | O15: 26.59052 | P15: 69.90739 | Q15: 18.74486 | R15: 65.7517 | S15: 28.89246 | T15: 73.27052 | U15: 17.47674 | V15: 65.60694 | W15: 17.47778 | X15: 65.57847 | Y15: 29.81215 | Z15: 54.31215 | AA15: 29.94792 | AB15: 53.54271 | AC15: 28.32917 | AD15: 58.63889 | AE15: 32.09653 | AF15: 58.71458 | AG15: 32.61597 | AH15: 54.92813
... A184: 46203 | B184: 2026 | C184: June | D184: ="Week-" & INT((DAY(A184)-1)/7)+1 -> Week-5 | E184: 17.137048 | F184: 56.170867 | G184: 20.493854 | H184: 53.900068 | I184: 29.144826 | J184: 58.337533 | K184: 29.760347 | L184: 56.176214 | M184: 29.798472 | N184: 56.396943 | O184: 29.89743 | P184: 55.861492 | Q184: 17.770277 | R184: 64.586943 | S184: 31.707395 | T184: 64.641075 | U184: 17.197917 | V184: 60.938889 | W184: 17.200347 | X184: 60.928472 | Y184: 26.5 | Z184: 44.5 | AA184: 26.200001 | AB184: 45.5 | AC184: 25.9 | AD184: 46.599998 | AE184: 39.200001 | AF184: 43.700001 | AG184: 37 | AH184: 45.700001
A185: 46204 | B185: 2026 | C185: July | D185: Week-1 | E185: 17.127777 | F185: 56.1842 | G185: 19.899409 | H185: 60.686214 | I185: 29.105659 | J185: 57.80177 | K185: 29.778437 | L185: 55.386284 | M185: 29.828645 | N185: 55.711943 | O185: 29.922013 | P185: 55.167429 | Q185: 18.810243 | R185: 64.024964 | S185: 31.45243 | T185: 64.89604 | U185: 17.457639 | V185: 62.370833 | W185: 17.457292 | X185: 62.350347 | Y185: 26.5 | Z185: 44.5 | AA185: 26.200001 | AB185: 45.5 | AC185: 25.9 | AD185: 46.599998 | AE185: 39.200001 | AF185: 43.700001 | AG185: 37 | AH185: 45.700001
A186: 46205 | B186: 2026 | C186: July | D186: Week-1 | E186: 17.143576 | F186: 56.933922 | G186: 20.510312 | H186: 59.04236 | I186: 29.038298 | J186: 59.063402 | K186: 29.540694 | L186: 57.214061 | M186: 29.581701 | N186: 57.42736 | O186: 29.705069 | P186: 56.674304 | Q186: 18.863055 | R186: 64.047221 | S186: 31.960867 | T186: 64.755867 | U186: 17.463889 | V186: 62.690625 | W186: 17.460764 | X186: 62.687153 | Y186: 26.5 | Z186: 44.5 | AA186: 26.200001 | AB186: 45.5 | AC186: 25.9 | AD186: 46.599998 | AE186: 39.200001 | AF186: 43.700001 | AG186: 37 | AH186: 45.700001
A187: 46206 | B187: 2026 | C187: July | D187: Week-1 | E187: 17.116423 | F187: 57.625485 | G187: 20.225937 | H187: 55.845311 | I187: 28.98052 | J187: 61.168436 | K187: 29.542291 | L187: 58.366908 | M187: 29.576562 | N187: 59.025485 | O187: 29.694166 | P187: 58.414235 | Q187: 19.009791 | R187: 63.672013 | S187: 31.868437 | T187: 65.007012 | U187: 17.462153 | V187: 63.117014 | W187: 17.464931 | X187: 63.109722 | Y187: 26.5 | Z187: 44.5 | AA187: 26.200001 | AB187: 45.5 | AC187: 25.9 | AD187: 46.599998 | AE187: 39.200001 | AF187: 43.700001 | AG187: 37 | AH187: 45.700001
A188: 46207 | B188: 2026 | C188: July | D188: Week-1 | E188: 17.146354 | F188: 57.863575 | G188: 20.186493 | H188: 56.300832 | I188: 28.90177 | J188: 62.198644 | K188: 29.526319 | L188: 59.203679 | M188: 29.572985 | N188: 60.004096 | O188: 29.655937 | P188: 59.529929 | Q188: 18.84927 | R188: 64.099825 | S188: 31.520069 | T188: 67.34545 | U188: 17.459028 | V188: 62.876042 | W188: 17.461458 | X188: 62.882639 | Y188: 26.5 | Z188: 44.5 | AA188: 26.200001 | AB188: 45.5 | AC188: 25.9 | AD188: 46.599998 | AE188: 39.200001 | AF188: 43.700001 | AG188: 37 | AH188: 45.700001
A189: 46208 | B189: 2026 | C189: July | D189: Week-1 | E189: 17.110902 | F189: 57.243714 | G189: 20.182708 | H189: 56.29111 | I189: 28.869305 | J189: 62.436179 | K189: 29.55677 | L189: 59.359443 | M189: 29.605624 | N189: 60.109478 | O189: 29.673472 | P189: 60.009269 | Q189: 19.021493 | R189: 63.699686 | S189: 30.853784 | T189: 67.899235 | U189: 17.462847 | V189: 63.145486 | W189: 17.462153 | X189: 63.145486 | Y189: 26.5 | Z189: 44.5 | AA189: 26.200001 | AB189: 45.5 | AC189: 25.9 | AD189: 46.599998 | AE189: 39.200001 | AF189: 43.700001 | AG189: 37 | AH189: 45.700001
A190: 46209 | B190: 2026 | C190: July | D190: Week-1 | E190: 17.11743 | F190: 57.245589 | G190: 20.22184 | H190: 55.156492 | I190: 28.864409 | J190: 61.33354 | K190: 29.559097 | L190: 58.450936 | M190: 29.609583 | N190: 59.195554 | O190: 29.694062 | P190: 58.601596 | Q190: 18.859062 | R190: 63.817846 | S190: 31.275763 | T190: 66.935381 | U190: 17.445833 | V190: 62.541667 | W190: 17.450347 | X190: 62.536806 | Y190: 26.5 | Z190: 44.5 | AA190: 26.200001 | AB190: 45.5 | AC190: 25.9 | AD190: 46.599998 | AE190: 39.200001 | AF190: 43.700001 | AG190: 37 | AH190: 45.700001
A191: 46210 | B191: 2026 | C191: July | D191: Week-1 | E191: 18.733541 | F191: 59.427186 | G191: 18.479097 | H191: 54.962429 | I191: 28.932361 | J191: 60.944408 | K191: 29.571527 | L191: 58.582117 | M191: 29.602708 | N191: 59.122707 | O191: 29.743888 | P191: 58.655346 | Q191: 19.044236 | R191: 63.32229 | S191: 31.575103 | T191: 65.169165 | U191: 17.45382 | V191: 62.751042 | W191: 17.451389 | X191: 62.747917 | Y191: 26.5 | Z191: 44.5 | AA191: 26.200001 | AB191: 45.5 | AC191: 25.9 | AD191: 46.599998 | AE191: 39.200001 | AF191: 43.700001 | AG191: 37 | AH191: 45.700001
A192: 46211 | B192: 2026 | C192: July | D192: Week-2 | E192: 19.036388 | F192: 51.616596 | G192: 18.78118 | H192: 58.788089 | I192: 29.025416 | J192: 60.075728 | K192: 29.67677 | L192: 57.234304 | M192: 29.72118 | N192: 58.110172 | O192: 29.827083 | P192: 57.154165 | Q192: 18.86118 | R192: 63.292255 | S192: 32.29736 | T192: 63.276908 | U192: 17.452431 | V192: 61.834722 | W192: 17.451389 | X192: 61.844444 | Y192: 26.5 | Z192: 44.5 | AA192: 26.200001 | AB192: 45.5 | AC192: 25.9 | AD192: 46.599998 | AE192: 39.200001 | AF192: 43.700001 | AG192: 37 | AH192: 45.700001
A193: 46212 | B193: 2026 | C193: July | D193: Week-2 | E193: 17.933055 | F193: 53.594964 | G193: 20.154305 | H193: 55.525485 | I193: 29.017638 | J193: 57.334686 | K193: 29.603055 | L193: 54.524096 | M193: 29.64986 | N193: 55.723436 | O193: 29.739444 | P193: 54.929547 | Q193: 19.061666 | R193: 62.871561 | S193: 31.869652 | T193: 59.145068 | U193: 17.471875 | V193: 62.051042 | W193: 17.482639 | X193: 62.065972 | Y193: 26.5 | Z193: 44.5 | AA193: 26.200001 | AB193: 45.5 | AC193: 25.9 | AD193: 46.599998 | AE193: 39.200001 | AF193: 43.700001 | AG193: 37 | AH193: 45.700001
A194: 46213 | B194: 2026 | C194: July | D194: Week-2 | E194: 17.479166 | F194: 58.871943 | G194: 20.25868 | H194: 55.881353 | I194: 28.847638 | J194: 58.110172 | K194: 29.427465 | L194: 55.341527 | M194: 29.463506 | N194: 56.386179 | O194: 29.553263 | P194: 55.796631 | Q194: 19.108507 | R194: 64.511318 | S194: 31.579722 | T194: 59.896943 | U194: 17.888542 | V194: 62.539236 | W194: 17.882639 | X194: 62.553472 | Y194: 26.5 | Z194: 44.5 | AA194: 26.200001 | AB194: 45.5 | AC194: 25.9 | AD194: 46.599998 | AE194: 39.200001 | AF194: 43.700001 | AG194: 37 | AH194: 45.700001
A195: 46214 | B195: 2026 | C195: July | D195: Week-2 | E195: 17.822361 | F195: 60.350589 | G195: 20.224895 | H195: 56.709929 | I195: 28.593159 | J195: 60.28111 | K195: 28.948992 | L195: 58.730068 | M195: 28.961492 | N195: 59.527186 | O195: 29.113263 | P195: 58.466769 | Q195: 19.94559 | R195: 65.560624 | S195: 31.044409 | T195: 61.59104 | U195: 18.559028 | V195: 64.344792 | W195: 18.562847 | X195: 64.336458 | Y195: 26.5 | Z195: 44.5 | AA195: 26.200001 | AB195: 45.5 | AC195: 25.9 | AD195: 46.599998 | AE195: 39.200001 | AF195: 43.700001 | AG195: 37 | AH195: 45.700001
A196: 46215 | B196: 2026 | C196: July | D196: Week-2 | E196: 17.857882 | F196: 60.209756 | G196: 20.274548 | H196: 56.888471 | I196: 28.364861 | J196: 60.009582 | K196: 28.792638 | L196: 57.872533 | M196: 28.812013 | N196: 58.547672 | O196: 28.962777 | P196: 57.587013 | Q196: 19.095173 | R196: 63.757429 | S196: 30.655347 | T196: 64.666839 | U196: 17.682639 | V196: 62.320139 | W196: 17.684375 | X196: 62.311806 | Y196: 26.5 | Z196: 44.5 | AA196: 26.200001 | AB196: 45.5 | AC196: 25.9 | AD196: 46.599998 | AE196: 39.200001 | AF196: 43.700001 | AG196: 37 | AH196: 45.700001
... A215: 46234 | B215: 2026 | C215: July | D215: Week-5 | E215: 20.273298 | F215: 58.65979 | G215: 18.881423 | H215: 60.639374 | I215: 29.152117 | J215: 62.703922 | K215: 29.61118 | L215: 61.015867 | M215: 29.658472 | N215: 61.789339 | O215: 29.779826 | P215: 61.248575 | Q215: 18.056736 | R215: 61.862464 | S215: 30.511735 | T215: 69.156353 | U215: 16.396875 | V215: 62.435417 | W215: 16.389236 | X215: 62.430208 | Y215: 32.183333 | Z215: 49.276042 | AA215: 32.557292 | AB215: 46.368403 | AC215: 31.242014 | AD215: 49.385764 | AE215: 33.663194 | AF215: 56.148958 | AG215: 34.283681 | AH215: 51.825347
A216: 46235 | B216: 2026 | C216: August | D216: ="Week-" & INT((DAY(A216)-1)/7)+1 -> Week-1 | E216: 22.175034 | F216: 56.250763 | G216: 18.415937 | H216: 56.116943 | I216: 29.264548 | J216: 61.746283 | K216: 29.67684 | L216: 59.919547 | M216: 29.69868 | N216: 60.997013 | O216: 29.826562 | P216: 60.6392 | Q216: 17.679514 | R216: 61.965485 | S216: 31.712708 | T216: 66.514131 | U216: 16.365625 | V216: 60.967708 | W216: 16.365625 | X216: 60.987153 | Y216: 32.307292 | Z216: 48.067014 | AA216: 32.667014 | AB216: 45.407292 | AC216: 31.316667 | AD216: 48.553125 | AE216: 34.829862 | AF216: 53.728472 | AG216: 35.421875 | AH216: 49.575347
A217: 46236 | B217: 2026 | C217: August | D217: ="Week-" & INT((DAY(A217)-1)/7)+1 -> Week-1 | E217: 20.678819 | F217: 51.701075 | G217: 18.849965 | H217: 60.747394 | I217: 29.413402 | J217: 61.40538 | K217: 29.884305 | L217: 59.528714 | M217: 29.899409 | N217: 60.324998 | O217: 30.022291 | P217: 60.678714 | Q217: 17.993437 | R217: 61.098158 | S217: 31.785902 | T217: 66.988922 | U217: 16.378472 | V217: 62.172222 | W217: 16.383334 | X217: 62.160764 | Y217: 32.462153 | Z217: 48.958333 | AA217: 32.848263 | AB217: 45.592708 | AC217: 31.510764 | AD217: 48.214583 | AE217: 35.032639 | AF217: 53.754167 | AG217: 35.567361 | AH217: 49.895139
A218: 46237 | B218: 2026 | C218: August | D218: ="Week-" & INT((DAY(A218)-1)/7)+1 -> Week-1 | E218: 18.634722 | F218: 54.291735 | G218: 20.176007 | H218: 57.59427 | I218: 29.444062 | J218: 60.967221 | K218: 29.838124 | L218: 58.901214 | M218: 29.859965 | N218: 60.012395 | O218: 29.987117 | P218: 59.962533 | Q218: 17.675937 | R218: 61.717464 | S218: 31.551631 | T218: 67.704895 | U218: 16.361111 | V218: 60.652778 | W218: 16.363889 | X218: 60.665625 | Y218: 32.458333 | Z218: 48.155903 | AA218: 32.804861 | AB218: 45.19375 | AC218: 31.471875 | AD218: 48.096528 | AE218: 34.751736 | AF218: 54.642708 | AG218: 35.220833 | AH218: 50.903472
A219: 46238 | B219: 2026 | C219: August | D219: ="Week-" & INT((DAY(A219)-1)/7)+1 -> Week-1 | E219: 17.962291 | F219: 55.980138 | G219: 20.230138 | H219: 56.721943 | I219: 29.448298 | J219: 58.869131 | K219: 29.821284 | L219: 56.184582 | M219: 29.841041 | N219: 57.079443 | O219: 29.982152 | P219: 57.375381 | Q219: 18.041701 | R219: 61.462985 | S219: 32.057499 | T219: 66.108992 | U219: 16.384722 | V219: 62.33368 | W219: 16.384375 | X219: 62.089236 | Y219: 32.442708 | Z219: 46.113542 | AA219: 32.796181 | AB219: 43.384722 | AC219: 31.436458 | AD219: 46.065625 | AE219: 35.380556 | AF219: 52.700695 | AG219: 35.837153 | AH219: 49.137847
A220: 46239 | B220: 2026 | C220: August | D220: ="Week-" & INT((DAY(A220)-1)/7)+1 -> Week-1 | E220: 18.046076 | F220: 55.983367 | G220: 20.250138 | H220: 57.201978 | I220: 29.516597 | J220: 60.628159 | K220: 29.888194 | L220: 58.450658 | M220: 29.891423 | N220: 58.936735 | O220: 30.066735 | P220: 59.292776 | Q220: 17.694652 | R220: 61.391318 | S220: 32.185833 | T220: 65.076492 | U220: 16.377778 | V220: 60.453125 | W220: 16.379861 | X220: 60.411458 | Y220: 32.540972 | Z220: 47.847917 | AA220: 32.921875 | AB220: 45.021181 | AC220: 31.605208 | AD220: 47.443403 | AE220: 35.418056 | AF220: 52.072569 | AG220: 35.809722 | AH220: 48.457639
A221: 46240 | B221: 2026 | C221: August | D221: ="Week-" & INT((DAY(A221)-1)/7)+1 -> Week-1 | E221: 17.96677 | F221: 57.856422 | G221: 20.339687 | H221: 56.795415 | I221: 29.389062 | J221: 55.952915 | K221: 29.607395 | L221: 55.60861 | M221: 29.636284 | N221: 55.980207 | O221: 29.807777 | P221: 54.919999 | Q221: 18.026423 | R221: 61.184478 | S221: 32.021249 | T221: 65.669304 | U221: 16.430209 | V221: 61.877778 | W221: 16.430209 | X221: 61.919792 | Y221: 32.295486 | Z221: 45.747222 | AA221: 32.672916 | AB221: 42.399653 | AC221: 31.370139 | AD221: 44.579514 | AE221: 35.395139 | AF221: 52.349306 | AG221: 35.832291 | AH221: 48.896875
A222: 46241 | B222: 2026 | C222: August | D222: ="Week-" & INT((DAY(A222)-1)/7)+1 -> Week-1 | E222: 17.950764 | F222: 57.460103 | G222: 20.371527 | H222: 56.91611 | I222: 29.372048 | J222: 60.343401 | K222: 29.717499 | L222: 59.172533 | M222: 29.767083 | N222: 59.164964 | O222: 29.868819 | P222: 59.44604 | Q222: 17.691389 | R222: 61.600033 | S222: 31.949548 | T222: 67.038124 | U222: 16.368056 | V222: 60.564931 | W222: 16.361111 | X222: 60.542708 | Y222: 32.380903 | Z222: 47.650347 | AA222: 32.746528 | AB222: 44.77882 | AC222: 31.417014 | AD222: 47.257292 | AE222: 35.144444 | AF222: 53.821181 | AG222: 35.603125 | AH222: 49.850695
A223: 46242 | B223: 2026 | C223: August | D223: ="Week-" & INT((DAY(A223)-1)/7)+1 -> Week-2 | E223: 19.360729 | F223: 59.805624 | G223: 18.550729 | H223: 55.584617 | I223: 29.307812 | J223: 58.239478 | K223: 29.674027 | L223: 56.476353 | M223: 29.709131 | N223: 56.771388 | O223: 29.830069 | P223: 56.649513 | Q223: 18.087187 | R223: 61.343853 | S223: 32.288367 | T223: 63.723089 | U223: 16.390278 | V223: 62.171875 | W223: 16.387847 | X223: 62.129861 | Y223: 32.271181 | Z223: 45.995139 | AA223: 32.623958 | AB223: 43.174653 | AC223: 31.274305 | AD223: 45.807292 | AE223: 35.691666 | AF223: 50.520139 | AG223: 36.067014 | AH223: 47.363889
A224: 46243 | B224: 2026 | C224: August | D224: ="Week-" & INT((DAY(A224)-1)/7)+1 -> Week-2 | E224: 19.303993 | F224: 51.156943 | G224: 18.92118 | H224: 59.537846 | I224: 29.366805 | J224: 56.54552 | K224: 29.686388 | L224: 55.55611 | M224: 29.721492 | N224: 55.808471 | O224: 29.855104 | P224: 55.451422 | Q224: 17.685243 | R224: 61.701144 | S224: 32.440034 | T224: 62.187429 | U224: 16.386458 | V224: 60.210417 | W224: 16.385764 | X224: 60.216667 | Y224: 32.359722 | Z224: 43.620486 | AA224: 32.702083 | AB224: 41.359028 | AC224: 31.352083 | AD224: 44.059375 | AE224: 35.659375 | AF224: 49.377431 | AG224: 36.063542 | AH224: 45.896528
A225: 46244 | B225: 2026 | C225: August | D225: ="Week-" & INT((DAY(A225)-1)/7)+1 -> Week-2 | E225: 18.8275 | F225: 49.268888 | G225: 20.10052 | H225: 56.549235 | I225: 29.368124 | J225: 55.127638 | K225: 29.81302 | L225: 53.563158 | M225: 29.843124 | N225: 53.762464 | O225: 29.970034 | P225: 53.493402 | Q225: 18.131632 | R225: 60.880033 | S225: 32.075833 | T225: 61.411804 | U225: 16.39132 | V225: 61.483681 | W225: 16.395834 | X225: 61.519444 | Y225: 32.346875 | Z225: 42.877083 | AA225: 32.69757 | AB225: 40.433681 | AC225: 31.327778 | AD225: 43.192014 | AE225: 35.21875 | AF225: 48.907986 | AG225: 35.714584 | AH225: 45.396875
A226: 46245 | B226: 2026 | C226: August | D226: ="Week-" & INT((DAY(A226)-1)/7)+1 -> Week-2 | E226: 19.620557 | F226: 57.701915 | G226: 20.192543 | H226: 57.235852 | I226: 27.339163 | J226: 59.360521 | K226: 27.055539 | L226: 59.154215 | M226: 27.125365 | N226: 59.193274 | O226: 27.027282 | P226: 59.679023 | Q226: 17.711254 | R226: 61.760277 | S226: 32.159442 | T226: 62.380556 | U226: 16.391638 | V226: 60.402788 | W226: 16.394077 | X226: 60.405227 | Y226: 29.225087 | Z226: 48.931707 | AA226: 29.217421 | AB226: 48.330314 | AC226: 27.991986 | AD226: 50.236237 | AE226: 35.358537 | AF226: 49.538676 | AG226: 35.762718 | AH226: 46.147038
...

Sheet Summary
A1: Year | B1: 2026
A2: Month | B2: August
A3: ROOM TEMPERATURE | H3: CRAC TEMPERATURE
A4: Measurement | B4: FunctLocation | C4: Location | D4: Date | E4: Temperature (˚ C) | F4: Humidity (%) | H4: Measurement | I4: FunctLocation | J4: Location | K4: Date | L4: Temperature (˚ C) | M4: Humidity (%)
A5: Battery | B5: 1st Floor | C5: Battery Room | D5: Week-1 | E5: =AVERAGEIFS(Database!$E:$E,Database!$B:$B,Summary!$B$1,Database!$C:$C,Summary!$B$2,Database!$D:$D,Summary!D5) -> 19.059211 | F5: =AVERAGEIFS(Database!$F:$F,Database!$B:$B,Summary!$B$1,Database!$C:$C,Summary!$B$2,Database!$D:$D,Summary!$D5) -> 55.646229 | H5: 2.1.A - CCG | I5: 2nd Floor | J5: CCG Room | K5: Week-1 | L5: =AVERAGEIFS(Database!$U:$U,Database!$B:$B,Summary!$B$1,Database!$C:$C,Summary!$B$2,Database!$D:$D,Summary!K5) -> 16.380853 | M5: =AVERAGEIFS(Database!$V:$V,Database!$B:$B,Summary!$B$1,Database!$C:$C,Summary!$B$2,Database!$D:$D,Summary!$K5) -> 61.288889
A6: Battery | B6: 1st Floor | C6: Battery Room | D6: Week-2 | E6: =AVERAGEIFS(Database!$E:$E,Database!$B:$B,Summary!$B$1,Database!$C:$C,Summary!$B$2,Database!$D:$D,Summary!D6) -> 19.544057 | F6: =AVERAGEIFS(Database!$F:$F,Database!$B:$B,Summary!$B$1,Database!$C:$C,Summary!$B$2,Database!$D:$D,Summary!$D6) -> 56.492157 | H6: 2.1.A - CCG | I6: 2nd Floor | J6: CCG Room | K6: Week-2 | L6: =AVERAGEIFS(Database!$E:$E,Database!$B:$B,Summary!$B$1,Database!$C:$C,Summary!$B$2,Database!$D:$D,Summary!K6) -> 19.544057 | M6: =AVERAGEIFS(Database!$V:$V,Database!$B:$B,Summary!$B$1,Database!$C:$C,Summary!$B$2,Database!$D:$D,Summary!$K6) -> 61.385914
A7: Battery | B7: 1st Floor | C7: Battery Room | D7: Week-3 | E7: =AVERAGEIFS(Database!$E:$E,Database!$B:$B,Summary!$B$1,Database!$C:$C,Summary!$B$2,Database!$D:$D,Summary!D7) -> 19.471636 | F7: =AVERAGEIFS(Database!$F:$F,Database!$B:$B,Summary!$B$1,Database!$C:$C,Summary!$B$2,Database!$D:$D,Summary!$D7) -> 59.99925 | H7: 2.1.A - CCG | I7: 2nd Floor | J7: CCG Room | K7: Week-3 | L7: =AVERAGEIFS(Database!$E:$E,Database!$B:$B,Summary!$B$1,Database!$C:$C,Summary!$B$2,Database!$D:$D,Summary!K7) -> 19.471636 | M7: =AVERAGEIFS(Database!$V:$V,Database!$B:$B,Summary!$B$1,Database!$C:$C,Summary!$B$2,Database!$D:$D,Summary!$K7) -> 61.47624
A8: Battery | B8: 1st Floor | C8: Battery Room | D8: Week-4 | E8: =AVERAGEIFS(Database!$E:$E,Database!$B:$B,Summary!$B$1,Database!$C:$C,Summary!$B$2,Database!$D:$D,Summary!D8) -> 19.68245 | F8: =AVERAGEIFS(Database!$F:$F,Database!$B:$B,Summary!$B$1,Database!$C:$C,Summary!$B$2,Database!$D:$D,Summary!$D8) -> 54.973387 | H8: 2.1.A - CCG | I8: 2nd Floor | J8: CCG Room | K8: Week-4 | L8: =AVERAGEIFS(Database!$E:$E,Database!$B:$B,Summary!$B$1,Database!$C:$C,Summary!$B$2,Database!$D:$D,Summary!K8) -> 19.68245 | M8: =AVERAGEIFS(Database!$V:$V,Database!$B:$B,Summary!$B$1,Database!$C:$C,Summary!$B$2,Database!$D:$D,Summary!$K8) -> 61.251686
A9: Measurement | B9: FunctLocation | C9: Location | D9: Date | E9: Actual (˚ C) | F9: Humidity (%) | H9: Measurement | I9: FunctLocation | J9: Location | K9: Date | L9: Temperature (˚ C) | M9: Humidity (%)
A10: Panel | B10: 1st Floor | C10: Panel Room | D10: Week-1 | E10: =AVERAGEIFS(Database!$G:$G,Database!$B:$B,Summary!$B$1,Database!$C:$C,Summary!$B$2,Database!$D:$D,Summary!D10) -> 19.804771 | F10: =AVERAGEIFS(Database!$H:$H,Database!$B:$B,Summary!$B$1,Database!$C:$C,Summary!$B$2,Database!$D:$D,Summary!$D10) -> 57.442008 | H10: 2.1.B - CCG | I10: 2nd Floor | J10: CCG Room | K10: Week-1 | L10: =AVERAGEIFS(Database!$W:$W,Database!$B:$B,Summary!$B$1,Database!$C:$C,Summary!$B$2,Database!$D:$D,Summary!K10) -> 16.381201 | M10: =AVERAGEIFS(Database!$X:$X,Database!$B:$B,Summary!$B$1,Database!$C:$C,Summary!$B$2,Database!$D:$D,Summary!$K10) -> 61.253819
A11: Panel | B11: 1st Floor | C11: Panel Room | D11: Week-2 | E11: =AVERAGEIFS(Database!$G:$G,Database!$B:$B,Summary!$B$1,Database!$C:$C,Summary!$B$2,Database!$D:$D,Summary!D11) -> 19.787724 | F11: =AVERAGEIFS(Database!$H:$H,Database!$B:$B,Summary!$B$1,Database!$C:$C,Summary!$B$2,Database!$D:$D,Summary!$D11) -> 57.412556 | H11: 2.1.B - CCG | I11: 2nd Floor | J11: CCG Room | K11: Week-2 | L11: =AVERAGEIFS(Database!$W:$W,Database!$B:$B,Summary!$B$1,Database!$C:$C,Summary!$B$2,Database!$D:$D,Summary!K11) -> 16.392606 | M11: =AVERAGEIFS(Database!$X:$X,Database!$B:$B,Summary!$B$1,Database!$C:$C,Summary!$B$2,Database!$D:$D,Summary!$K11) -> 61.397969
A12: Panel | B12: 1st Floor | C12: Panel Room | D12: Week-3 | E12: =AVERAGEIFS(Database!$G:$G,Database!$B:$B,Summary!$B$1,Database!$C:$C,Summary!$B$2,Database!$D:$D,Summary!D12) -> 20.47303 | F12: =AVERAGEIFS(Database!$H:$H,Database!$B:$B,Summary!$B$1,Database!$C:$C,Summary!$B$2,Database!$D:$D,Summary!$D12) -> 63.377027 | H12: 2.1.B - CCG | I12: 2nd Floor | J12: CCG Room | K12: Week-3 | L12: =AVERAGEIFS(Database!$W:$W,Database!$B:$B,Summary!$B$1,Database!$C:$C,Summary!$B$2,Database!$D:$D,Summary!K12) -> 16.371677 | M12: =AVERAGEIFS(Database!$X:$X,Database!$B:$B,Summary!$B$1,Database!$C:$C,Summary!$B$2,Database!$D:$D,Summary!$K12) -> 61.455109
A13: Panel | B13: 1st Floor | C13: Panel Room | D13: Week-4 | E13: =AVERAGEIFS(Database!$G:$G,Database!$B:$B,Summary!$B$1,Database!$C:$C,Summary!$B$2,Database!$D:$D,Summary!D13) -> 19.308382 | F13: =AVERAGEIFS(Database!$H:$H,Database!$B:$B,Summary!$B$1,Database!$C:$C,Summary!$B$2,Database!$D:$D,Summary!$D13) -> 61.312682 | H13: 2.1.B - CCG | I13: 2nd Floor | J13: CCG Room | K13: Week-4 | L13: =AVERAGEIFS(Database!$W:$W,Database!$B:$B,Summary!$B$1,Database!$C:$C,Summary!$B$2,Database!$D:$D,Summary!K13) -> 16.396082 | M13: =AVERAGEIFS(Database!$X:$X,Database!$B:$B,Summary!$B$1,Database!$C:$C,Summary!$B$2,Database!$D:$D,Summary!$K13) -> 61.268552
A14: Measurement | B14: FunctLocation | C14: Location | D14: Date | E14: Actual (˚ C) | F14: Humidity (%) | H14: Measurement | I14: FunctLocation | J14: Location | K14: Date | L14: Temperature (˚ C) | M14: Humidity (%)
A15: Data Center | B15: 1st Floor | C15: Data Center | D15: Week-1 | E15: =AVERAGEIFS(Database!$I:$I,Database!$B:$B,Summary!$B$1,Database!$C:$C,Summary!$B$2,Database!$D:$D,Summary!D15) -> 29.406859 | F15: =AVERAGEIFS(Database!$J:$J,Database!$B:$B,Summary!$B$1,Database!$C:$C,Summary!$B$2,Database!$D:$D,Summary!$D15) -> 59.987499 | H15: 2.2.A - Data Center | I15: 2nd Floor | J15: Data Center | K15: Week-1 | L15: =AVERAGEIFS(Database!$Y:$Y,Database!$B:$B,Summary!$B$1,Database!$C:$C,Summary!$B$2,Database!$D:$D,Summary!K15) -> 32.41255 | M15: =AVERAGEIFS(Database!$Z:$Z,Database!$B:$B,Summary!$B$1,Database!$C:$C,Summary!$B$2,Database!$D:$D,Summary!$K15) -> 47.505754
A16: Data Center | B16: 1st Floor | C16: Data Center | D16: Week-2 | E16: =AVERAGEIFS(Database!$I:$I,Database!$B:$B,Summary!$B$1,Database!$C:$C,Summary!$B$2,Database!$D:$D,Summary!D16) -> 28.596705 | F16: =AVERAGEIFS(Database!$J:$J,Database!$B:$B,Summary!$B$1,Database!$C:$C,Summary!$B$2,Database!$D:$D,Summary!$D16) -> 58.923045 | H16: 2.2.A - Data Center | I16: 2nd Floor | J16: Data Center | K16: Week-2 | L16: =AVERAGEIFS(Database!$Y:$Y,Database!$B:$B,Summary!$B$1,Database!$C:$C,Summary!$B$2,Database!$D:$D,Summary!K16) -> 31.525211 | M16: =AVERAGEIFS(Database!$Z:$Z,Database!$B:$B,Summary!$B$1,Database!$C:$C,Summary!$B$2,Database!$D:$D,Summary!$K16) -> 46.377645
A17: Data Center | B17: 1st Floor | C17: Data Center | D17: Week-3 | E17: =AVERAGEIFS(Database!$I:$I,Database!$B:$B,Summary!$B$1,Database!$C:$C,Summary!$B$2,Database!$D:$D,Summary!D17) -> 29.278382 | F17: =AVERAGEIFS(Database!$J:$J,Database!$B:$B,Summary!$B$1,Database!$C:$C,Summary!$B$2,Database!$D:$D,Summary!$D17) -> 60.524165 | H17: 2.2.A - Data Center | I17: 2nd Floor | J17: Data Center | K17: Week-3 | L17: =AVERAGEIFS(Database!$Y:$Y,Database!$B:$B,Summary!$B$1,Database!$C:$C,Summary!$B$2,Database!$D:$D,Summary!K17) -> 32.288343 | M17: =AVERAGEIFS(Database!$Z:$Z,Database!$B:$B,Summary!$B$1,Database!$C:$C,Summary!$B$2,Database!$D:$D,Summary!$K17) -> 47.956597
A18: Data Center | B18: 1st Floor | C18: Data Center | D18: Week-4 | E18: =AVERAGEIFS(Database!$I:$I,Database!$B:$B,Summary!$B$1,Database!$C:$C,Summary!$B$2,Database!$D:$D,Summary!D18) -> 29.325773 | F18: =AVERAGEIFS(Database!$J:$J,Database!$B:$B,Summary!$B$1,Database!$C:$C,Summary!$B$2,Database!$D:$D,Summary!$D18) -> 57.746348 | H18: 2.2.A - Data Center | I18: 2nd Floor | J18: Data Center | K18: Week-4 | L18: =AVERAGEIFS(Database!$Y:$Y,Database!$B:$B,Summary!$B$1,Database!$C:$C,Summary!$B$2,Database!$D:$D,Summary!K18) -> 32.263194 | M18: =AVERAGEIFS(Database!$Z:$Z,Database!$B:$B,Summary!$B$1,Database!$C:$C,Summary!$B$2,Database!$D:$D,Summary!$K18) -> 45.612054
A19: Measurement | B19: FunctLocation | C19: Location | D19: Date | E19: Actual (˚ C) | F19: Humidity (%) | H19: Measurement | I19: FunctLocation | J19: Location | K19: Date | L19: Temperature (˚ C) | M19: Humidity (%)
A20: CCG | B20: 2nd Floor | C20: CCG Room | D20: Week-1 | E20: =AVERAGEIFS(Database!$Q:$Q,Database!$B:$B,Summary!$B$1,Database!$C:$C,Summary!$B$2,Database!$D:$D,Summary!D20) -> 17.829008 | F20: =AVERAGEIFS(Database!$R:$R,Database!$B:$B,Summary!$B$1,Database!$C:$C,Summary!$B$2,Database!$D:$D,Summary!$D20) -> 61.48856 | H20: 2.2.B - Data Center | I20: 2nd Floor | J20: Data Center | K20: Week-1 | L20: =AVERAGEIFS(Database!$AA:$AA,Database!$B:$B,Summary!$B$1,Database!$C:$C,Summary!$B$2,Database!$D:$D,Summary!K20) -> 32.779663 | M20: =AVERAGEIFS(Database!$AB:$AB,Database!$B:$B,Summary!$B$1,Database!$C:$C,Summary!$B$2,Database!$D:$D,Summary!$K20) -> 44.539732
A21: CCG | B21: 2nd Floor | C21: CCG Room | D21: Week-2 | E21: =AVERAGEIFS(Database!$Q:$Q,Database!$B:$B,Summary!$B$1,Database!$C:$C,Summary!$B$2,Database!$D:$D,Summary!D21) -> 17.91758 | F21: =AVERAGEIFS(Database!$R:$R,Database!$B:$B,Summary!$B$1,Database!$C:$C,Summary!$B$2,Database!$D:$D,Summary!$D21) -> 61.570386 | H21: 2.2.B - Data Center | I21: 2nd Floor | J21: Data Center | K21: Week-2 | L21: =AVERAGEIFS(Database!$AA:$AA,Database!$B:$B,Summary!$B$1,Database!$C:$C,Summary!$B$2,Database!$D:$D,Summary!K21) -> 31.744106 | M21: =AVERAGEIFS(Database!$AB:$AB,Database!$B:$B,Summary!$B$1,Database!$C:$C,Summary!$B$2,Database!$D:$D,Summary!$K21) -> 44.330422
A22: CCG | B22: 2nd Floor | C22: CCG Room | D22: Week-3 | E22: =AVERAGEIFS(Database!$Q:$Q,Database!$B:$B,Summary!$B$1,Database!$C:$C,Summary!$B$2,Database!$D:$D,Summary!D22) -> 17.838105 | F22: =AVERAGEIFS(Database!$R:$R,Database!$B:$B,Summary!$B$1,Database!$C:$C,Summary!$B$2,Database!$D:$D,Summary!$D22) -> 61.591591 | H22: 2.2.B - Data Center | I22: 2nd Floor | J22: Data Center | K22: Week-3 | L22: =AVERAGEIFS(Database!$AA:$AA,Database!$B:$B,Summary!$B$1,Database!$C:$C,Summary!$B$2,Database!$D:$D,Summary!K22) -> 32.684474 | M22: =AVERAGEIFS(Database!$AB:$AB,Database!$B:$B,Summary!$B$1,Database!$C:$C,Summary!$B$2,Database!$D:$D,Summary!$K22) -> 44.843948
A23: CCG | B23: 2nd Floor | C23: CCG Room | D23: Week-4 | E23: =AVERAGEIFS(Database!$Q:$Q,Database!$B:$B,Summary!$B$1,Database!$C:$C,Summary!$B$2,Database!$D:$D,Summary!D23) -> 17.84245 | F23: =AVERAGEIFS(Database!$R:$R,Database!$B:$B,Summary!$B$1,Database!$C:$C,Summary!$B$2,Database!$D:$D,Summary!$D23) -> 61.350405 | H23: 2.2.B - Data Center | I23: 2nd Floor | J23: Data Center | K23: Week-4 | L23: =AVERAGEIFS(Database!$AA:$AA,Database!$B:$B,Summary!$B$1,Database!$C:$C,Summary!$B$2,Database!$D:$D,Summary!K23) -> 32.656101 | M23: =AVERAGEIFS(Database!$AB:$AB,Database!$B:$B,Summary!$B$1,Database!$C:$C,Summary!$B$2,Database!$D:$D,Summary!$K23) -> 42.69003
A24: Measurement | B24: FunctLocation | C24: Location | D24: Date | E24: Actual (˚ C) | F24: Humidity (%) | H24: Measurement | I24: FunctLocation | J24: Location | K24: Date | L24: Temperature (˚ C) | M24: Humidity (%)
A25: META | B25: 2nd Floor | C25: Meta Room | D25: Week-1 | E25: =AVERAGEIFS(Database!$O:$O,Database!$B:$B,Summary!$B$1,Database!$C:$C,Summary!$B$2,Database!$D:$D,Summary!D25) -> 29.937351 | F25: =AVERAGEIFS(Database!$P:$P,Database!$B:$B,Summary!$B$1,Database!$C:$C,Summary!$B$2,Database!$D:$D,Summary!$D25) -> 58.902092 | H25: 2.2.C - Data Center | I25: 2nd Floor | J25: Data Center | K25: Week-1 | L25: =AVERAGEIFS(Database!$AC:$AC,Database!$B:$B,Summary!$B$1,Database!$C:$C,Summary!$B$2,Database!$D:$D,Summary!K25) -> 31.446875 | M25: =AVERAGEIFS(Database!$AD:$AD,Database!$B:$B,Summary!$B$1,Database!$C:$C,Summary!$B$2,Database!$D:$D,Summary!$K25) -> 47.172867
A26: META | B26: 2nd Floor | C26: Meta Room | D26: Week-2 | E26: =AVERAGEIFS(Database!$O:$O,Database!$B:$B,Summary!$B$1,Database!$C:$C,Summary!$B$2,Database!$D:$D,Summary!D26) -> 29.092488 | F26: =AVERAGEIFS(Database!$P:$P,Database!$B:$B,Summary!$B$1,Database!$C:$C,Summary!$B$2,Database!$D:$D,Summary!$D26) -> 57.574587 | H26: 2.2.C - Data Center | I26: 2nd Floor | J26: Data Center | K26: Week-2 | L26: =AVERAGEIFS(Database!$AC:$AC,Database!$B:$B,Summary!$B$1,Database!$C:$C,Summary!$B$2,Database!$D:$D,Summary!K26) -> 30.483875 | M26: =AVERAGEIFS(Database!$AD:$AD,Database!$B:$B,Summary!$B$1,Database!$C:$C,Summary!$B$2,Database!$D:$D,Summary!$K26) -> 46.639105
A27: META | B27: 2nd Floor | C27: Meta Room | D27: Week-3 | E27: =AVERAGEIFS(Database!$O:$O,Database!$B:$B,Summary!$B$1,Database!$C:$C,Summary!$B$2,Database!$D:$D,Summary!D27) -> 29.752296 | F27: =AVERAGEIFS(Database!$P:$P,Database!$B:$B,Summary!$B$1,Database!$C:$C,Summary!$B$2,Database!$D:$D,Summary!$D27) -> 59.935584 | H27: 2.2.C - Data Center | I27: 2nd Floor | J27: Data Center | K27: Week-3 | L27: =AVERAGEIFS(Database!$AC:$AC,Database!$B:$B,Summary!$B$1,Database!$C:$C,Summary!$B$2,Database!$D:$D,Summary!K27) -> 31.361161 | M27: =AVERAGEIFS(Database!$AD:$AD,Database!$B:$B,Summary!$B$1,Database!$C:$C,Summary!$B$2,Database!$D:$D,Summary!$K27) -> 47.383978
A28: META | B28: 2nd Floor | C28: Meta Room | D28: Week-4 | E28: =AVERAGEIFS(Database!$O:$O,Database!$B:$B,Summary!$B$1,Database!$C:$C,Summary!$B$2,Database!$D:$D,Summary!D28) -> 29.751537 | F28: =AVERAGEIFS(Database!$P:$P,Database!$B:$B,Summary!$B$1,Database!$C:$C,Summary!$B$2,Database!$D:$D,Summary!$D28) -> 57.028387 | H28: 2.2.C - Data Center | I28: 2nd Floor | J28: Data Center | K28: Week-4 | L28: =AVERAGEIFS(Database!$AC:$AC,Database!$B:$B,Summary!$B$1,Database!$C:$C,Summary!$B$2,Database!$D:$D,Summary!K28) -> 31.323214 | M28: =AVERAGEIFS(Database!$AD:$AD,Database!$B:$B,Summary!$B$1,Database!$C:$C,Summary!$B$2,Database!$D:$D,Summary!$K28) -> 45.263095
A29: Measurement | B29: FunctLocation | C29: Location | D29: Date | E29: Actual (˚ C) | F29: Humidity (%) | H29: Measurement | I29: FunctLocation | J29: Location | K29: Date | L29: Temperature (˚ C) | M29: Humidity (%)
A30: GOOGLE 1 | B30: 2nd Floor | C30: Google Room | D30: Week-1 | E30: =AVERAGEIFS(Database!$K:$K,Database!$B:$B,Summary!$B$1,Database!$C:$C,Summary!$B$2,Database!$D:$D,Summary!D30) -> 29.776234 | F30: =AVERAGEIFS(Database!$L:$L,Database!$B:$B,Summary!$B$1,Database!$C:$C,Summary!$B$2,Database!$D:$D,Summary!$D30) -> 58.252266 | H30: 3.1.A - TPN | I30: 3rd Floor | J30: TPN Room | K30: Week-1 | L30: =AVERAGEIFS(Database!$AE:$AE,Database!$B:$B,Summary!$B$1,Database!$C:$C,Summary!$B$2,Database!$D:$D,Summary!K30) -> 35.136062 | M30: =AVERAGEIFS(Database!$AF:$AF,Database!$B:$B,Summary!$B$1,Database!$C:$C,Summary!$B$2,Database!$D:$D,Summary!$K30) -> 53.295585
A31: GOOGLE 1 | B31: 2nd Floor | C31: Google Room | D31: Week-2 | E31: =AVERAGEIFS(Database!$K:$K,Database!$B:$B,Summary!$B$1,Database!$C:$C,Summary!$B$2,Database!$D:$D,Summary!D31) -> 28.965538 | F31: =AVERAGEIFS(Database!$L:$L,Database!$B:$B,Summary!$B$1,Database!$C:$C,Summary!$B$2,Database!$D:$D,Summary!$D31) -> 57.436796 | H31: 3.1.A - TPN | I31: 3rd Floor | J31: TPN Room | K31: Week-2 | L31: =AVERAGEIFS(Database!$AE:$AE,Database!$B:$B,Summary!$B$1,Database!$C:$C,Summary!$B$2,Database!$D:$D,Summary!K31) -> 35.361091 | M31: =AVERAGEIFS(Database!$AF:$AF,Database!$B:$B,Summary!$B$1,Database!$C:$C,Summary!$B$2,Database!$D:$D,Summary!$K31) -> 49.853243
A32: GOOGLE 1 | B32: 2nd Floor | C32: Google Room | D32: Week-3 | E32: =AVERAGEIFS(Database!$K:$K,Database!$B:$B,Summary!$B$1,Database!$C:$C,Summary!$B$2,Database!$D:$D,Summary!D32) -> 29.595719 | F32: =AVERAGEIFS(Database!$L:$L,Database!$B:$B,Summary!$B$1,Database!$C:$C,Summary!$B$2,Database!$D:$D,Summary!$D32) -> 59.715867 | H32: 3.1.A - TPN | I32: 3rd Floor | J32: TPN Room | K32: Week-3 | L32: =AVERAGEIFS(Database!$AE:$AE,Database!$B:$B,Summary!$B$1,Database!$C:$C,Summary!$B$2,Database!$D:$D,Summary!K32) -> 35.166071 | M32: =AVERAGEIFS(Database!$AF:$AF,Database!$B:$B,Summary!$B$1,Database!$C:$C,Summary!$B$2,Database!$D:$D,Summary!$K32) -> 53.098165
A33: GOOGLE 1 | B33: 2nd Floor | C33: Google Room | D33: Week-4 | E33: =AVERAGEIFS(Database!$K:$K,Database!$B:$B,Summary!$B$1,Database!$C:$C,Summary!$B$2,Database!$D:$D,Summary!D33) -> 29.607365 | F33: =AVERAGEIFS(Database!$L:$L,Database!$B:$B,Summary!$B$1,Database!$C:$C,Summary!$B$2,Database!$D:$D,Summary!$D33) -> 56.827945 | H33: 3.1.A - TPN | I33: 3rd Floor | J33: TPN Room | K33: Week-4 | L33: =AVERAGEIFS(Database!$AE:$AE,Database!$B:$B,Summary!$B$1,Database!$C:$C,Summary!$B$2,Database!$D:$D,Summary!K33) -> 35.254018 | M33: =AVERAGEIFS(Database!$AF:$AF,Database!$B:$B,Summary!$B$1,Database!$C:$C,Summary!$B$2,Database!$D:$D,Summary!$K33) -> 50.577728
A34: Measurement | B34: FunctLocation | C34: Location | D34: Date | E34: Actual (˚ C) | F34: Humidity (%) | H34: Measurement | I34: FunctLocation | J34: Location | K34: Date | L34: Temperature (˚ C) | M34: Humidity (%)
A35: GOOGLE 2 | B35: 2nd Floor | C35: Google Room | D35: Week-1 | E35: =AVERAGEIFS(Database!$M:$M,Database!$B:$B,Summary!$B$1,Database!$C:$C,Summary!$B$2,Database!$D:$D,Summary!D35) -> 29.799126 | F35: =AVERAGEIFS(Database!$N:$N,Database!$B:$B,Summary!$B$1,Database!$C:$C,Summary!$B$2,Database!$D:$D,Summary!$D35) -> 58.927965 | H35: 3.1.B - TPN | I35: 3rd Floor | J35: TPN Room | K35: Week-1 | L35: =AVERAGEIFS(Database!$AG:$AG,Database!$B:$B,Summary!$B$1,Database!$C:$C,Summary!$B$2,Database!$D:$D,Summary!K35) -> 35.613194 | M35: =AVERAGEIFS(Database!$AH:$AH,Database!$B:$B,Summary!$B$1,Database!$C:$C,Summary!$B$2,Database!$D:$D,Summary!$K35) -> 49.531002
A36: GOOGLE 2 | B36: 2nd Floor | C36: Google Room | D36: Week-2 | E36: =AVERAGEIFS(Database!$M:$M,Database!$B:$B,Summary!$B$1,Database!$C:$C,Summary!$B$2,Database!$D:$D,Summary!D36) -> 29.004144 | F36: =AVERAGEIFS(Database!$N:$N,Database!$B:$B,Summary!$B$1,Database!$C:$C,Summary!$B$2,Database!$D:$D,Summary!$D36) -> 57.699073 | H36: 3.1.B - TPN | I36: 3rd Floor | J36: TPN Room | K36: Week-2 | L36: =AVERAGEIFS(Database!$AG:$AG,Database!$B:$B,Summary!$B$1,Database!$C:$C,Summary!$B$2,Database!$D:$D,Summary!K36) -> 35.787283 | M36: =AVERAGEIFS(Database!$AH:$AH,Database!$B:$B,Summary!$B$1,Database!$C:$C,Summary!$B$2,Database!$D:$D,Summary!$K36) -> 46.508555
A37: GOOGLE 2 | B37: 2nd Floor | C37: Google Room | D37: Week-3 | E37: =AVERAGEIFS(Database!$M:$M,Database!$B:$B,Summary!$B$1,Database!$C:$C,Summary!$B$2,Database!$D:$D,Summary!D37) -> 29.633184 | F37: =AVERAGEIFS(Database!$N:$N,Database!$B:$B,Summary!$B$1,Database!$C:$C,Summary!$B$2,Database!$D:$D,Summary!$D37) -> 59.740599 | H37: 3.1.B - TPN | I37: 3rd Floor | J37: TPN Room | K37: Week-3 | L37: =AVERAGEIFS(Database!$AG:$AG,Database!$B:$B,Summary!$B$1,Database!$C:$C,Summary!$B$2,Database!$D:$D,Summary!K37) -> 35.598909 | M37: =AVERAGEIFS(Database!$AH:$AH,Database!$B:$B,Summary!$B$1,Database!$C:$C,Summary!$B$2,Database!$D:$D,Summary!$K37) -> 49.538988
A38: GOOGLE 2 | B38: 2nd Floor | C38: Google Room | D38: Week-4 | E38: =AVERAGEIFS(Database!$M:$M,Database!$B:$B,Summary!$B$1,Database!$C:$C,Summary!$B$2,Database!$D:$D,Summary!D38) -> 29.640371 | F38: =AVERAGEIFS(Database!$N:$N,Database!$B:$B,Summary!$B$1,Database!$C:$C,Summary!$B$2,Database!$D:$D,Summary!$D38) -> 56.953436 | H38: 3.1.B - TPN | I38: 3rd Floor | J38: TPN Room | K38: Week-4 | L38: =AVERAGEIFS(Database!$AG:$AG,Database!$B:$B,Summary!$B$1,Database!$C:$C,Summary!$B$2,Database!$D:$D,Summary!K38) -> 35.668502 | M38: =AVERAGEIFS(Database!$AH:$AH,Database!$B:$B,Summary!$B$1,Database!$C:$C,Summary!$B$2,Database!$D:$D,Summary!$K38) -> 47.323016
A39: Measurement | B39: FunctLocation | C39: Location | D39: Date | E39: Actual (˚ C) | F39: Humidity (%)
A40: TPN | B40: 3rd Floor | C40: TPN Room | D40: Week-1 | E40: =AVERAGEIFS(Database!$S:$S,Database!$B:$B,Summary!$B$1,Database!$C:$C,Summary!$B$2,Database!$D:$D,Summary!D40) -> 31.89491 | F40: =AVERAGEIFS(Database!$T:$T,Database!$B:$B,Summary!$B$1,Database!$C:$C,Summary!$B$2,Database!$D:$D,Summary!$D40) -> 66.44298
...
